2025-09-02 06:59:00 - root - INFO - [SETUP] Logging system initialized with level: INFO
2025-09-02 06:59:00 - main - INFO - [STARTUP] Initializing Syria GPT FastAPI application...
2025-09-02 06:59:00 - main - INFO - [ROUTER] All API routers included successfully
2025-09-02 06:59:00 - uvicorn.error - INFO - Started server process [26]
2025-09-02 06:59:00 - uvicorn.error - INFO - Waiting for application startup.
2025-09-02 06:59:00 - main - INFO - [STARTUP] Starting Syria GPT application...
2025-09-02 06:59:00 - services.ai.intelligent_qa_service - INFO - ðŸš€ Initializing Enhanced Syria GPT Q&A system...
2025-09-02 06:59:00 - httpx - INFO - HTTP Request: GET http://qdrant:6333/collections "HTTP/1.1 200 OK"
2025-09-02 06:59:01 - httpx - INFO - HTTP Request: PUT http://qdrant:6333/collections/syria_qa_vectors "HTTP/1.1 200 OK"
2025-09-02 06:59:01 - services.ai.qdrant_service - INFO - Created Qdrant collection: syria_qa_vectors
2025-09-02 06:59:01 - services.ai.embedding_service - ERROR - Failed to generate embedding for text: Invalid model name: 'embedding-001'. Model names should start with 'models/' or 'tunedModels/'.
2025-09-02 06:59:01 - services.ai.embedding_service - ERROR - GenAI API embedding failed: Embedding generation failed: Invalid model name: 'embedding-001'. Model names should start with 'models/' or 'tunedModels/'.
Traceback (most recent call last):
  File "/app/services/ai/embedding_service.py", line 73, in generate_embedding
    result = await asyncio.get_event_loop().run_in_executor(
             ^^^^^^^^^^^^^^^^^^^^^^^^^^^^^^^^^^^^^^^^^^^^^^^
    ...<5 lines>...
    )
    ^
  File "/usr/local/lib/python3.13/concurrent/futures/thread.py", line 59, in run
    result = self.fn(*self.args, **self.kwargs)
  File "/app/services/ai/embedding_service.py", line 75, in <lambda>
    lambda: self.client.embed_content(
            ~~~~~~~~~~~~~~~~~~~~~~~~~^
        model=self.model_name,
        ^^^^^^^^^^^^^^^^^^^^^^
        content=text_item
        ^^^^^^^^^^^^^^^^^
    )
    ^
  File "/usr/local/lib/python3.13/site-packages/google/generativeai/embedding.py", line 163, in embed_content
    model = model_types.make_model_name(model)
  File "/usr/local/lib/python3.13/site-packages/google/generativeai/types/model_types.py", line 362, in make_model_name
    raise ValueError(
        f"Invalid model name: '{name}'. Model names should start with 'models/' or 'tunedModels/'."
    )
ValueError: Invalid model name: 'embedding-001'. Model names should start with 'models/' or 'tunedModels/'.

During handling of the above exception, another exception occurred:

Traceback (most recent call last):
  File "/app/services/ai/embedding_service.py", line 124, in generate_embedding
    raise RuntimeError(f"Embedding generation failed: {e}")
RuntimeError: Embedding generation failed: Invalid model name: 'embedding-001'. Model names should start with 'models/' or 'tunedModels/'.
