2025-09-07 13:40:14 - services.ai.embedding_service - ERROR - [embedding_service.py:116] - generate_embedding() - Embedding generation failed (attempt 1/3): 504 Deadline Exceeded
2025-09-07 13:41:13 - services.ai.embedding_service - ERROR - [embedding_service.py:116] - generate_embedding() - Embedding generation failed (attempt 2/3): Timeout of 60.0s exceeded, last exception: 503 failed to connect to all addresses; last error: UNKNOWN: ipv4:142.251.36.42:443: Failed to connect to remote host: Timeout occurred: FD Shutdown
2025-09-07 13:42:14 - services.ai.embedding_service - ERROR - [embedding_service.py:116] - generate_embedding() - Embedding generation failed (attempt 3/3): Timeout of 60.0s exceeded, last exception: 503 failed to connect to all addresses; last error: UNKNOWN: ipv4:172.217.23.202:443: Handshake read failed
2025-09-07 13:42:14 - services.ai.embedding_service - ERROR - [embedding_service.py:122] - generate_embedding() - All 3 attempts failed. Final error: Timeout of 60.0s exceeded, last exception: 503 failed to connect to all addresses; last error: UNKNOWN: ipv4:172.217.23.202:443: Handshake read failed
2025-09-07 13:43:12 - services.ai.embedding_service - ERROR - [embedding_service.py:116] - generate_embedding() - Embedding generation failed (attempt 1/3): Timeout of 60.0s exceeded, last exception: 503 failed to connect to all addresses; last error: UNKNOWN: ipv4:142.251.36.10:443: Failed to connect to remote host: Timeout occurred: FD Shutdown
2025-09-07 13:44:08 - services.ai.embedding_service - ERROR - [embedding_service.py:116] - generate_embedding() - Embedding generation failed (attempt 2/3): Timeout of 60.0s exceeded, last exception: 503 failed to connect to all addresses; last error: UNAVAILABLE: ipv4:142.250.179.202:443: Socket closed
2025-09-07 13:45:03 - services.ai.embedding_service - ERROR - [embedding_service.py:116] - generate_embedding() - Embedding generation failed (attempt 3/3): Timeout of 60.0s exceeded, last exception: 503 failed to connect to all addresses; last error: UNAVAILABLE: ipv4:142.250.179.138:443: Socket closed
2025-09-07 13:45:03 - services.ai.embedding_service - ERROR - [embedding_service.py:122] - generate_embedding() - All 3 attempts failed. Final error: Timeout of 60.0s exceeded, last exception: 503 failed to connect to all addresses; last error: UNAVAILABLE: ipv4:142.250.179.138:443: Socket closed
2025-09-07 19:23:11 - services.auth.auth - ERROR - [logging_config.py:231] - log_error_with_context() - [ERROR] Error in verify_token: Signature has expired. - Context: {'token_length': 145, 'duration': 0.005016326904296875}
2025-09-07 19:23:11 - services.dependencies - ERROR - [dependencies.py:34] - get_current_user() - Token verification failed - payload is None
2025-09-07 19:23:11 - services.database.database - ERROR - [logging_config.py:231] - log_error_with_context() - [ERROR] Error in get_db: 401: Could not validate credentials - Context: {'duration': 0.03585457801818848}
2025-09-07 19:23:11 - services.database.database - ERROR - [database.py:50] - get_db() - ‚ùå Failed to create database session: 401: Could not validate credentials
