2025-09-02 06:59:00 - root - INFO - [logging_config.py:157] - setup_logging() - [SETUP] Logging system initialized with level: INFO
2025-09-02 06:59:00 - main - INFO - [main.py:32] - <module>() - [STARTUP] Initializing Syria GPT FastAPI application...
2025-09-02 06:59:00 - main - INFO - [main.py:204] - <module>() - [ROUTER] All API routers included successfully
2025-09-02 06:59:00 - uvicorn.error - INFO - [server.py:84] - _serve() - Started server process [26]
2025-09-02 06:59:00 - uvicorn.error - INFO - [on.py:48] - startup() - Waiting for application startup.
2025-09-02 06:59:00 - main - INFO - [main.py:298] - startup_event() - [STARTUP] Starting Syria GPT application...
2025-09-02 06:59:00 - services.ai.intelligent_qa_service - DEBUG - [logging_config.py:205] - log_function_entry() - [ENTER] Entering function: initialize_system with params: {}
2025-09-02 06:59:00 - services.ai.intelligent_qa_service - INFO - [intelligent_qa_service.py:67] - initialize_system() - ðŸš€ Initializing Enhanced Syria GPT Q&A system...
2025-09-02 06:59:00 - httpx - INFO - [_client.py:1013] - _send_single_request() - HTTP Request: GET http://qdrant:6333/collections "HTTP/1.1 200 OK"
2025-09-02 06:59:01 - httpx - INFO - [_client.py:1013] - _send_single_request() - HTTP Request: PUT http://qdrant:6333/collections/syria_qa_vectors "HTTP/1.1 200 OK"
2025-09-02 06:59:01 - services.ai.qdrant_service - INFO - [qdrant_service.py:64] - _ensure_collection_exists() - Created Qdrant collection: syria_qa_vectors
2025-09-02 06:59:01 - services.ai.embedding_service - ERROR - [embedding_service.py:123] - generate_embedding() - Failed to generate embedding for text: Invalid model name: 'embedding-001'. Model names should start with 'models/' or 'tunedModels/'.
2025-09-02 06:59:01 - services.ai.embedding_service - ERROR - [embedding_service.py:129] - generate_embedding() - GenAI API embedding failed: Embedding generation failed: Invalid model name: 'embedding-001'. Model names should start with 'models/' or 'tunedModels/'.
Traceback (most recent call last):
  File "/app/services/ai/embedding_service.py", line 73, in generate_embedding
    result = await asyncio.get_event_loop().run_in_executor(
             ^^^^^^^^^^^^^^^^^^^^^^^^^^^^^^^^^^^^^^^^^^^^^^^
    ...<5 lines>...
    )
    ^
  File "/usr/local/lib/python3.13/concurrent/futures/thread.py", line 59, in run
    result = self.fn(*self.args, **self.kwargs)
  File "/app/services/ai/embedding_service.py", line 75, in <lambda>
    lambda: self.client.embed_content(
            ~~~~~~~~~~~~~~~~~~~~~~~~~^
        model=self.model_name,
        ^^^^^^^^^^^^^^^^^^^^^^
        content=text_item
        ^^^^^^^^^^^^^^^^^
    )
    ^
  File "/usr/local/lib/python3.13/site-packages/google/generativeai/embedding.py", line 163, in embed_content
    model = model_types.make_model_name(model)
  File "/usr/local/lib/python3.13/site-packages/google/generativeai/types/model_types.py", line 362, in make_model_name
    raise ValueError(
        f"Invalid model name: '{name}'. Model names should start with 'models/' or 'tunedModels/'."
    )
ValueError: Invalid model name: 'embedding-001'. Model names should start with 'models/' or 'tunedModels/'.

During handling of the above exception, another exception occurred:

Traceback (most recent call last):
  File "/app/services/ai/embedding_service.py", line 124, in generate_embedding
    raise RuntimeError(f"Embedding generation failed: {e}")
RuntimeError: Embedding generation failed: Invalid model name: 'embedding-001'. Model names should start with 'models/' or 'tunedModels/'.
